
Exception while resolving variable 'name' in template 'unknown'.
Traceback (most recent call last):
  File "C:\Users\juhan\AppData\Local\Programs\Python\Python36-32\lib\site-packages\django\core\handlers\exception.py", line 34, in inner
    response = get_response(request)
  File "C:\Users\juhan\AppData\Local\Programs\Python\Python36-32\lib\site-packages\django\core\handlers\base.py", line 111, in _get_response
    resolver_match = resolver.resolve(request.path_info)
  File "C:\Users\juhan\AppData\Local\Programs\Python\Python36-32\lib\site-packages\django\urls\resolvers.py", line 520, in resolve
    raise Resolver404({'tried': tried, 'path': new_path})
django.urls.exceptions.Resolver404: {'tried': [[<URLResolver <URLPattern list> (admin:admin) 'admin/'>], [<URLResolver <module 'mapapp.urls' from 'C:\\Users\\juhan\\gis-dev-proj\\mapapp\\urls.py'> (None:None) ''>, <URLPattern '' [name='Map View']>]], 'path': '12'}

During handling of the above exception, another exception occurred:

Traceback (most recent call last):
  File "C:\Users\juhan\AppData\Local\Programs\Python\Python36-32\lib\site-packages\django\template\base.py", line 829, in _resolve_lookup
    current = current[bit]
TypeError: 'URLResolver' object is not subscriptable

During handling of the above exception, another exception occurred:

Traceback (most recent call last):
  File "C:\Users\juhan\AppData\Local\Programs\Python\Python36-32\lib\site-packages\django\template\base.py", line 837, in _resolve_lookup
    current = getattr(current, bit)
AttributeError: 'URLResolver' object has no attribute 'name'

During handling of the above exception, another exception occurred:

Traceback (most recent call last):
  File "C:\Users\juhan\AppData\Local\Programs\Python\Python36-32\lib\site-packages\django\template\base.py", line 843, in _resolve_lookup
    current = current[int(bit)]
ValueError: invalid literal for int() with base 10: 'name'

During handling of the above exception, another exception occurred:

Traceback (most recent call last):
  File "C:\Users\juhan\AppData\Local\Programs\Python\Python36-32\lib\site-packages\django\template\base.py", line 850, in _resolve_lookup
    (bit, current))  # missing attribute
django.template.base.VariableDoesNotExist: Failed lookup for key [name] in <URLResolver <URLPattern list> (admin:admin) 'admin/'>
Not Found: /12
"GET /12 HTTP/1.1" 404 2113
Watching for file changes with StatReloader
Waiting for apps ready_event.
Main Django thread has terminated before apps are ready.
